Workbook

Sheet 証明書
D1: 芽室町 証明交付申請書 | T1: 氏名 | U1: カナ氏名 | V1: 生年月日 | W1: 性別 | X1: 世帯主名 | Y1: 住所 | Z1: 番地 | AA1: 方書 | AB1: 本籍 | AC1: 筆頭者 | AD1: 住民コード | AE1: 世帯コード | AF1: 住所FULL | AJ1: 氏名 | AK1: カナ氏名 | AL1: 生年月日 | AM1: 性別 | AN1: 住所 | AO1: 番地 | AP1: 方書 | AQ1: 世帯主名 | AR1: 本籍 | AS1: 筆頭者 | AT1: 住民コード | AU1: 世帯コード | AV1: 住所FULL
R2: =AS2 -> 乙川 二郎 | T2: 乙川 二郎 | U2: オツカワ ジロウ | V2: 16851 | W2: 男 | X2: 乙川 二郎 | Y2: 中央二丁目２番地 | Z2: ２番地 | AB2: サンプル県サンプル市中央二丁目２番地 | AC2: 乙川 二郎 | AD2: 6 | AE2: 200 | AF2: 芽室町中央二丁目２番地 | AG2: 昭21. 2.18 | AJ2: 乙川 二郎 | AK2: オツカワ ジロウ | AL2: 16851 | AM2: 男 | AN2: 中央二丁目２番地 | AQ2: 乙川 二郎 | AR2: サンプル県サンプル市中央二丁目２番地 | AS2: 乙川 二郎 | AT2: 6 | AU2: 200 | AV2: 昭21. 2.18 | BA2: 0 | BB2: 0 | BC2: 0 | BD2: 0 | BE2: 0
A3: 芽室町長様 | V3: =DATEVALUE(SUBSTITUTE(SUBSTITUTE(V2," ",""),".","/")) -> #VALUE! | AL3: =DATEVALUE(SUBSTITUTE(SUBSTITUTE(AL2," ",""),".","/")) -> #VALUE! | AN3: ="芽室町"&AN2&AO2&" "&AP2 -> 芽室町中央二丁目２番地
F4: 下記のとおり申請いたします。
A6: ●１．窓口に来られた方
A7: 氏名 | B7: フリガナ | C7: =U2 -> オツカワ ジロウ | E7: 自署 | H7: 申請日 | J7: =TODAY() -> 46316
C8: =T2 -> 乙川 二郎 | H8: 生年月日 | J8: =V2 -> 16851
A10: 住所 | B10: =AF2 -> 芽室町中央二丁目２番地
A12: ●２．どなたの証明が必要ですか（証明対象者）
A13: 氏名 | B13: □１と同じ | C13: =IF(ISBLANK(AK2),"",AK2) -> オツカワ ジロウ | H13: 申請者からみた 続柄 | J13: =IF(EXACT(C7,C13),"本人","本人・夫婦・子・父母・祖父母・孫・その他( )") -> 本人
B14: (記入不要) | C14: =IF(ISBLANK(AJ2),"",AJ2) -> 乙川 二郎 | H14: 生年月日 | J14: =IF(ISERR(AL2),"",AL2) -> 16851
A16: 住所 | B16: □１と同じ | C16: =IF(ISBLANK(AN2),"",AN3) -> 芽室町中央二丁目２番地 | J16: 世帯主 | L16: □１と同じ (記入不要) | M16: =IF(OR(ISBLANK(AQ2),AQ2=0),"",AQ2) -> 乙川 二郎
B17: (記入不要)
A18: 本籍 | B18: ※戸籍に関する証明が必要な場合のみ記載してください | J18: 筆頭者 | L18: □１と同じ (記入不要) | M18: =IF(ISBLANK(AS2),"",AS2) -> 乙川 二郎
B19: □１の住所と同じ (記入不要) | C19: =IF(ISBLANK(AR2),"",AR2) -> サンプル県サンプル市中央二丁目２番地
A20: 使用 目的 | B20: □年金・恩給 □免許・資格取得 □学校・就職 □登記 □相続 □パスポート □車の購入・名義変更・廃車 □その他（ ）
A22: ●３．申請する証明書 | G22: (広域交付) | AA22: 左側
A23: 住民票 | B23: □世帯全員(謄本) | D23: 200 | F23: 通 | I23: 税に 関する証明 | J23: □課税証明 | M23: 200 | P23: 通 | AA23: =IF(E23>=1,"100000001000"&CHAR(13)&"*"&E23&CHAR(13),"") | AB23: =IF(G23>=1,"100000009000"&CHAR(13)&"*"&G23&CHAR(13),"") | AF23: =IF(N23>=1,"110000003000"&CHAR(13)&"*"&N23&CHAR(13),"")
B24: □世帯一部(抄本) | D24: 200 | F24: 通 | J24: □所得証明 | M24: 200 | P24: 通 | AA24: =IF(E24>=1,"100000002000"&CHAR(13)&"*"&E24&CHAR(13),"") | AB24: =IF(G24>=1,"100000010000"&CHAR(13)&"*"&G24&CHAR(13),"") | AF24: =IF(N24>=1,"110000002000"&CHAR(13)&"*"&N24&CHAR(13),"")
B25: □除票（謄本） | D25: 200 | F25: 通 | J25: □営業証明 | M25: 400 | P25: 通 | AA25: =IF(E25>=1,"100000003000"&CHAR(13)&"*"&E25&CHAR(13),"") | AF25: =IF(N25>=1,"110000004000"&CHAR(13)&"*"&N25&CHAR(13),"")
B26: □除票（抄本） | D26: 200 | F26: 通 | J26: □評価証明 | M26: 200 | O26: 合計 円 | AA26: =IF(E26>=1,"100000003000"&CHAR(13)&"*"&E26&CHAR(13),"") | AF26: =IF(N26>=1,"110000005000"&CHAR(13)&"*"&N26&CHAR(13),"")
B27: □記載事項証明 | D27: 200 | F27: 通 | J27: １筆増すごとに加算 | M27: 50 | O27: =IF(N26=0,"",M26*N26+M27*N27) | AA27: =IF(E27>=1,"100000004000"&CHAR(13)&"*"&E27&CHAR(13),"") | AF27: =IF(N27>=1,"110000006000"&CHAR(13)&"*"&N27&CHAR(13),"")
B28: ■いずれかを選択 本籍・筆頭者の記載 世帯主・続柄 個人番号 住民票コード | D28: =CHAR(10)&IF(BB2=0,"■不要 □必要","□不要 ■必要")&CHAR(10)&IF(BC2=0,"■不要 □必要","□不要 ■必要")&CHAR(10)&IF(BD2=0,"■不要 □必要","□不要 ■必要")&CHAR(10)&IF(BE2=0,"■不要 □必要","□不要 ■必要")&CHAR(10) -> ■不要 □必要 ■不要 □必要 ■不要 □必要 ■不要 □必要 | J28: □公課証明 | M28: 200 | P28: 通 | AF28: =IF(N28>=1,"110000008000"&CHAR(13)&"*"&N28&CHAR(13),"")
J29: □所有証明 | M29: 200 | P29: 通 | AF29: =IF(N29>=1,"110000007000"&CHAR(13)&"*"&N29&CHAR(13),"")
J30: □固定資産課税台帳(名寄帳） | M30: 無料 | P30: 通
A31: 戸籍に関する証明 | B31: □戸籍全員(謄本) | D31: 450 | F31: 通 | J31: □償却資産課税台帳 | M31: 無料 | P31: 通 | T31: 5070424 | AA31: =IF(E31>=1,"101000001000"&CHAR(13)&"*"&E31&CHAR(13),"") | AB31: =IF(G31>=1,"101000018000"&CHAR(13)&"*"&G31&CHAR(13),"")
B32: □戸籍一部(抄本) | D32: 450 | F32: 通 | J32: □固定資産明細書再発行 | M32: 無料 | P32: 通 | AA32: =IF(E32>=1,"101000002000"&CHAR(13)&"*"&E32&CHAR(13),"")
B33: □除籍全員(謄本) | D33: 750 | F33: 通 | J33: □納税証明 | M33: 200 | P33: 通 | T33: \\memfs181\共有ディスク\800共通業務\窓口BPR\database\csv | AA33: =IF(E33>=1,"101000003000"&CHAR(13)&"*"&E33&CHAR(13),"") | AB33: =IF(G33>=1,"101000019000"&CHAR(13)&"*"&G33&CHAR(13),"") | AF33: =IF(N33>=1,"110000001000"&CHAR(13)&"*"&N33&CHAR(13),"")
B34: □除籍一部(抄本) | D34: 750 | F34: 通 | I34: 各種 証明 | J34: □年金現況届 | M34: 200 | P34: 通 | AA34: =IF(E34>=1,"101000004000"&CHAR(13)&"*"&E34&CHAR(13),"") | AF34: =IF(N34>=1,"100000015000"&CHAR(13)&"*"&N34&CHAR(13),"")
B35: □改製原(平成・昭和) | D35: 750 | F35: 通 | J35: □不在証明 | M35: 200 | P35: 通 | AA35: =IF(E35>=1,"101000005000"&CHAR(13)&"*"&E35&CHAR(13),"") | AB35: =IF(G35>=1,"101000020000"&CHAR(13)&"*"&G35&CHAR(13),"") | AF35: =IF(N35>=1,"100000006000"&CHAR(13)&"*"&N35&CHAR(13),"")
B36: □附票(現在・改製原・除票) | D36: 200 | F36: 通 | J36: □受理証明 | M36: 350 | P36: 通 | AA36: =IF(E36>=1,"101000006000"&CHAR(13)&"*"&E36&CHAR(13),"") | AF36: =IF(N36>=1,"101000007000"&CHAR(13)&"*"&N36&CHAR(13),"")
B37: □身分証明書 | D37: 200 | F37: 通 | J37: □外国人登録済証明 | P37: 通 | AA37: =IF(E37>=1,"101000021000"&CHAR(13)&"*"&E37&CHAR(13),"") | AF37: =IF(N37>=1,"120000001000"&CHAR(13)&"*"&N37&CHAR(13),"")
B38: □記載事項証明 | D38: 350 | F38: 通 | J38: □その他( ) | P38: 通 | AA38: =IF(E38>=1,"101000010000"&CHAR(13)&"*"&E38&CHAR(13),"") | AF38: =IF(N38>=1,"120000006000"&CHAR(13)&"*"&M38&CHAR(13)&"*"&N38,"")
A39: 印鑑 証明 | B39: □印鑑証明書 | D39: 200 | F39: 通 | I39: 合計 | J39: =IF(SUM(E23:E27,E31:E40,N23:N25,N26,N28:N38,G23:G27,G31:G40)=0,"",SUM(E23:E27,E31:E40,N23:N25,N26,N27,N28:N38,G23:G27,G31:G40)) | K39: 通 | L39: =IF(SUM(R39:Y39)=0,"",SUM(R39:Y39)) | M39: 円 | N39: 担当 | R39: =IF(ISERR(SUMPRODUCT(D23:D27,E23:E27)),0,SUMPRODUCT(D23:D27,E23:E27)) -> 0 | S39: =IF(ISERR(SUMPRODUCT(D31:D40,E31:E40)),0,SUMPRODUCT(D31:D40,E31:E40)) -> 0 | T39: =IF(ISERR(SUMPRODUCT(M23:M25,N23:N25)),0,SUMPRODUCT(M23:M25,N23:N25)) -> 0 | U39: =IF(ISERR(SUMPRODUCT(M26:M27,N26:N27)),0,SUMPRODUCT(M26:M27,N26:N27)) -> 0 | V39: =IF(ISERR(SUMPRODUCT(M28:M29,N28:N29)),0,SUMPRODUCT(M28:M29,N28:N29)) -> 0 | W39: =IF(ISERR(SUMPRODUCT(M33:M38,N33:N38)),0,SUMPRODUCT(M33:M38,N33:N38)) -> 0 | X39: =IF(ISERR(SUMPRODUCT(D23:D27,G23:G27)),0,SUMPRODUCT(D23:D27,G23:G27)) -> 0 | Y39: =IF(ISERR(SUMPRODUCT(D31:D40,G31:G40)),0,SUMPRODUCT(D31:D40,G31:G40)) -> 0 | AA39: =IF(E39>=1,"100000005000"&CHAR(13)&"*"&E39&CHAR(13),"")
B40: □カード紛失・再発行・改印 | D40: 200 | F40: 通 | AA40: =IF(E40>=1,"100000014000"&CHAR(13)&"*"&E40&CHAR(13),"") | AF40: =IF(N40>=1,"110000007000"&CHAR(13)&"*"&N40&CHAR(13),"")
AA41: =AA23&AA24&AA25&AA26&AA27&AA31&AA32&AA33&AA34&AA35&AA36&AA37&AA38&AA39&AA40&AB23&AB24&AB31&AB33&AB35 | AF41: =AF23&AF24&AF25&AF26&AF27&AF28&AF29&AF33&AF34&AF35&AF36&AF37&AF38
A42: 本人 確認 | B42: □運転免許証 □マイナンバーカード □保険証(社保・国保・介護・後期) □学生証 □子ども医療費受給者証 □パスポート □委任状 □通帳 □その他( )
B52: 住基・戸籍・印鑑 | F52: 税・各種

Sheet 印鑑
B2: （第１号様式）
E3: 印鑑登録原票
B4: 登録印鑑 | F4: 氏名 | H4: =証明書!AJ2 -> 乙川 二郎
F5: 生年月日 | H5: =証明書!AL2 -> 16851 | P5: 性別 | R5: =証明書!AM2 -> 男
F6: 住所 | H6: ="北海道河西郡芽室町"&証明書!AN2 -> 北海道河西郡芽室町中央二丁目２番地
B9: 印鑑登録番号 | J9: 登録年月日 | M9: =TODAY() -> 46316
B12: 北海道河西郡芽室町長 様 | M12: =TODAY() -> 46316
B14: □印鑑登録申請書 | F14: □印鑑登録廃止申請書 （１ 印鑑亡失 ２ 登録証亡失 ３ 改印 ４ その他 ）
B15: 申 請 人 | C15: □本人 | I15: □代理人
C17: 署名 | I17: 氏名
I18: 生年月日 | L18: 大正・昭和・平成 | P18: 年 | R18: 月 | S18: 日
I19: 住所
I21: 電話番号
B23: 自動交付機の利用を希望する場合は、下記に暗証番号をご記入ください。
B24: ※４けたの数字で設定してください。
B26: ● | C26: 住民票交付用
B28: ● | C28: 印鑑登録証明書交付用
B32: （事務処理欄）
B34: 本 人 確 認 | C34: □マイナンバーカード | H34: □健康保険証 | K34: □本人回答 | O34: 旧印鑑登録番号
C35: □運転免許証 | H35: □介護保険証 | K35: □代理人回答
C36: □パスポート | H36: □年金手帳
C37: □身体障害者手帳 | H37: □その他 | O37: 自動交付機利用
C38: □在留カード | O38: ■希望あり □希望なし

Sheet マイナ暗証
I5: 個人番号カード暗証番号変更・再設定
I6: 電子証明書暗証番号変更・再設定
I7: 申請書
D10: 芽室町長 様
AD12: =TODAY() -> 46316
D13: 個人番号 | P13: 生年月日 ※ | T13: =証明書!AL2 -> 16851 | AE13: 性別 ※ | AH13: =証明書!AM2 -> 男
D17: 氏名 | H17: =証明書!AJ2 -> 乙川 二郎
D20: 住所 | H20: ="北海道河西郡"&証明書!AN3 -> 北海道河西郡芽室町中央二丁目２番地
D26: 電話番号
D30: ※ | E30: 個人番号がわからない場合は、生年月日と性別を記載してください。
D32: 申請の内容について、該当する番号に○をつけてください。
D33: 申請内容 | H33: 1.署名用電子証明書 | W33: 2.利用者証明用電子証明書
H34: 1.暗証番号の変更 2.暗証番号の再設定 ※暗証番号の初期化および変更を行います。 | W34: 1.暗証番号の変更 2.暗証番号の再設定 ※暗証番号の初期化および変更を行います。
H38: 3.住民基本台帳用 | W38: 4.券面事項入力補助用
H39: 1.暗証番号の変更 2.暗証番号の再設定 ※暗証番号の初期化および変更を行います。 | W39: 1.暗証番号の変更 2.暗証番号の再設定 ※暗証番号の初期化および変更を行います。
D44: 代理人による届出の場合は、以下に記入してください。
D45: 代理人 | X45: 本人との関係
D48: 住所
D53: 電話番号
D58: ※ | E58: 事務処理記載欄
D59: 受付担当者 | W59: 受付年月日
W60: 令和 年 月 日
D63: （参考）個人番号の記載がある場合は、生年月日と性別に加えて、住所の記載も省略することが可能です。

Sheet 電子更新・新規
E4: 地方公共団体情報システム機構 御中
E6: 署名用電子証明書／利用者証明用電子証明書 新規発行／更新申請書
E8: 1． | F8: 必要事項
E9: 以下に申請される方の氏名、住所等と申請の年月日をご記入ください。また、代理人を通じて申請される場合は代理人の氏名、住所等も併せてご記入ください。
E10: ふりがな | G10: =証明書!C13 -> オツカワ ジロウ
E11: 氏名 | G11: =証明書!AJ2 -> 乙川 二郎
E12: ふりがな
E13: 旧氏又は通称（※）
G16: ="北海道河西郡"&証明書!AN3 -> 北海道河西郡芽室町中央二丁目２番地
E17: 住所
E20: 電話番号 | K20: （ | N20: ）
E22: 生年月日 | G22: =証明書!AL2 -> 16851 | M22: 男女の別 | N22: =証明書!AM2 -> 男 | Q22: 申請の 年月日
S23: =TODAY() -> 46316
E25: 代理人 の氏名 | Q25: 本人との関係
E28: 代理人 の住所
E31: 代理人の 電話番号
K32: （ | N32: ）
E34: ※ 住民票に旧氏が記載されている方は、必ず旧氏を記載してください。
E35: ※ 外国籍を有する方で住民票に通称が記載されている方は、必ず通称を記載してください。
E36: ※ 申請する電子証明書の種類に○を付けてください。なお、15歳未満の方又は成年被後見人の方は、
E37: 原則として利用者証明用電子証明書のみの発行となります。
E38: 2．申請内容
E39: (1)又は(2)のどちらかにチェックを記入してください。
E40: (1)電子証明書の暗証番号を設定する
E41: 新規発行/更新の申請をする電子証明書の項目a又はｂに○を付けてください。
F42: 1. 署名用電子証明書の | N42: a．新規発行 b．更新
F43: 2. 利用者証明用電子証明書の | N43: a．新規発行 b．更新
E45: (2)電子証明書の暗証番号を設定しない（顔認証マイナンバーカード）
F46: 利用者証明用電子証明書のみ発行を行います。
F47: 顔認証マイナンバーカードの利用者証明用電子証明書は、健康保険証としての利用は可能ですが、マイナポータルなど暗証番号の入力を必要とする各種オンラインサービスでは利用できません。
E49: 3．代替対象文字の有無
E50: 申請される方の住所、氏名のコンピュータ入力に際して、画面上に正確に表示されない文字（代替対象文字）があることを経験上ご存知の場合は、有に○を付けてください。また、そのような場合に常用されている文字があれば、代わりに置き換える文字を選択する際の参考とするため、ご記入ください。 お分かりにならない場合は、ご記入いただく必要はございません。
E51: 代替対象 文字 の有無 | L51: 常用している文字 | N51: （例． →吉）
H52: （ 無 ・ 有 ）
E56: ※事務処理記載欄
E57: 受付担当者 | O57: 受付年月日
O58: 令和 年 月 日
E60: 署名用電子証明書 | F60: 通信の有無 | L60: 破棄／職権失効の有無と回数 | S60: 発行手数料額
F61: 1．無 | L61: 1．無 | S61: 円
F62: 2．有 （ ）回 | L62: 2．有 （ ）回
...

Sheet マイナ紛失
M4: 個人番号カード紛失・廃止届
D5: 電子証明書 失効申請/秘密鍵漏えい等届出書
D7: 芽室町長 様
AD9: =TODAY() -> 46316
D10: 個人番号 | P10: 生年月日 ※１ | T10: =証明書!AL2 -> 16851 | AD10: 性別 ※１ | AG10: =証明書!AM2 -> 男
D13: 氏名 | H13: =証明書!AJ2 -> 乙川 二郎
D16: 住所 | H16: ="北海道河西郡"&証明書!AN3 -> 北海道河西郡芽室町中央二丁目２番地
D19: 電話番号
D21: 紛失の経緯
D25: 遺失届を 届け出た 警察署※２
I26: （ | P26: ） | Q26: 警察署 | U26: 電話番号 | Y26: （ | AB26: ） | AE26: －
D28: 遺失届受理 番号※２
D30: ※１ 個人番号がわからない場合は、生年月日と性別を記載してください。
D31: ※２ 個人番号カードの再交付を希望しない場合は、遺失届を届け出た警察署及び遺失届受理番号は記載不要です。
D33: 失効申請等について、該当するものに○を付けてください。また、失効を希望される電子証明書のシリアル番号を確認できる資料（個人番号カード、電子証明書の写し等）を本日お持ちいただいている場合にはその旨と、もしその番号をお分かりになる場合には併せてそれもご記入ください。 なお、個人番号カードをお持ちいただいている場合は、失効した電子証明書及びその鍵ペアを当該個人番号カードより消去いたしますので、あらかじめご了承ください。
D38: 署名用 電子証明書 | H38: シリアル番号 | V38: 資料の有無 | AB38: （無・有）
H39: 1. サービス利用の自発的な取り止め 2. 利用者の秘密鍵の漏えい等 （例：個人番号カードの紛失・破損・盗難・廃止、暗証番号の漏えい等）
D42: 利用者証明用 電子証明書 | H42: シリアル番号 | V42: 資料の有無 | AB42: （無・有）
H43: 1. サービス利用の自発的な取り止め 2. 利用者の秘密鍵の漏えい等 （例：個人番号カードの紛失・破損・盗難・廃止、暗証番号の漏えい等）
D47: 代理人による届出の場合は、以下に記入してください。
D48: 代理人 | X48: 本人との関係
D51: 住所
D54: 電話番号
D58: ※ | E58: 事務処理記載欄
D59: 受付担当者 | W59: 受付年月日
W60: 令和 年 月 日
D63: （参考）個人番号の記載がある場合は、生年月日と性別に加えて、住所の記載も省略することが可能です。

Sheet 通知カード紛失
D5: 通知カード紛失届
D7: 芽室町長 様
AD9: =TODAY() -> 46316
D10: 個人番号 | P10: 生年月日 ※１ | T10: =証明書!AL2 -> 16851 | AD10: 性別 ※１ | AG10: =証明書!AM2 -> 男
D14: 氏名 | H14: =証明書!AJ2 -> 乙川 二郎
D18: 住所 | H18: ="北海道河西郡"&証明書!AN3 -> 北海道河西郡芽室町中央二丁目２番地
D24: 電話番号
D28: 紛失の経緯
D36: 遺失届を 届け出た 警 察 署 ※２
I37: （ | P37: ） | Q37: 警察署
I39: 電話番号 | M39: （ | P39: ） | S39: －
D41: 遺 失 届 受理番号 ※２
D44: ※１ 個人番号がわからない場合は、生年月日と性別を記載してください。
D45: ※２ 通知カードの再交付を希望しない場合は、遺失届を届け出た警察署及び遺失届受理番号は記載不要です。
D47: 代理人による届出の場合は、下記に記入してください。
D48: 代理人 | H48: ㊞ | X48: 本人との関係
D52: 住所
D56: 電話番号
D61: ※ | E61: 事務処理記載欄
D62: 受付担当者 | W62: 受付年月日
W63: 令和 年 月 日
D66: （参考）・個人番号の記載がある場合は、生年月日と性別に加えて、住所の記載も省略することが可能です。
F67: ・本届出書の提出と同時に個人番号カードの交付申請を行う場合は、「遺失届を届け出た警察署」 及び「遺失届受理番号」の記載を省略することが可能です。

Sheet マイナ券面（異動翌日以降）
J4: 個人番号カード 券面記載事項変更届 電子証明書 新規発行申請書
D8: 芽室町長 様
AD9: =TODAY() -> 46316
D10: 個人番号 | P10: 生年月日 ※ | T10: =証明書!AL2 -> 16851 | AD10: 性別 ※ | AG10: =証明書!AM2 -> 男
D12: 氏名 | H12: =証明書!AJ2 -> 乙川 二郎
D14: 住所
D16: 電話番号
D18: 変更理由 | H18: 転居 ・ 転入
D20: ※ | E20: 個人番号がわからない場合は、生年月日と性別を記載してください。
D22: 変更のある事項について以下に記入してください。
D23: 新しい生年月日 | V23: 新しい性別 | AB23: 男・女
D25: 新しい氏名
D27: 新しい住所 | J27: ="北海道河西郡"&証明書!AN3 -> 北海道河西郡芽室町中央二丁目２番地
D30: 旧氏に関する事項について届け出る場合は、以下のいずれかの□欄にチェックをつけてください。旧氏の記載・変更にチェックをつけた場合は、その旧氏を記入してください。
D32: 旧氏の記載・変更 □ | X32: 旧氏の削除 □
D35: 通称に関する事項について届け出る場合は、以下のいずれかの□欄にチェックをつけてください。通称の記載にチェックをつけた場合は、その通称を記入してください。
D37: 通称の記載 □ | X37: 通称の削除 □
D40: 券面記載事項の変更に伴い失効する署名用電子証明書を発行する場合、□欄にチェックをつけてください。
D41: 申請内容 | J41: 署名用電子証明書の発行 □
D44: 代替対象 文字 の有無を以下に記入してください。
D45: 代替対象文字 の有無 | J45: （ 無 ・ 有 ） | O45: 常用している文字 | V45: （例． →吉）
D48: ※ | E48: 申請される方の住所、氏名のコンピュータ入力に際して、画面上に正確に表示されない文字（代替対象文字）があることを経験上ご存知の場合は、有に○を付けてください。 また、そのような場合に常用されている文字があれば、代わりに置き換える文字を選択する際の参考とするため、記入してください。分からない場合は、記入していただく必要はございません。
D49: 代理人による届出の場合は、以下に記入してください。
D50: 代理人 | X50: 本人との関係
D52: 住所
D54: 電話番号
D58: ※ 事務処理記載欄
D59: 受付担当者 | T59: 受付年月日
T60: 令和 年 月 日
D62: 署名用 電子証明書 | F62: 通信の有無 | P62: 破棄／職権失効の有無と回数 | AA62: 発行手数料額
F63: 1．無 2．有 （ ）回 | P63: 1．無 2．有 （ ）回 | AA63: 円
F65: 無通信、破棄／職権失効及び発行手数料無料の理由
D68: （参考）個人番号の記載がある場合は、生年月日と性別に加えて、住所の記載も省略することが可能です。

Sheet マイナ券面（異動日）
J4: 個人番号カード 券面記載事項変更届 電子証明書 新規発行申請書
D8: 芽室町長 様
AD9: =TODAY() -> 46316
D10: 個人番号 | P10: 生年月日 ※ | T10: =証明書!AL2 -> 16851 | AD10: 性別 ※ | AG10: =証明書!AM2 -> 男
D12: 氏名 | H12: =証明書!AJ2 -> 乙川 二郎
D14: 住所 | H14: ="北海道河西郡"&証明書!AN3 -> 北海道河西郡芽室町中央二丁目２番地
D16: 電話番号
D18: 変更理由 | H18: 転居
D20: ※ | E20: 個人番号がわからない場合は、生年月日と性別を記載してください。
D22: 変更のある事項について以下に記入してください。
D23: 新しい生年月日 | V23: 新しい性別 | AB23: 男・女
D25: 新しい氏名
D27: 新しい住所
D30: 旧氏に関する事項について届け出る場合は、以下のいずれかの□欄にチェックをつけてください。旧氏の記載・変更にチェックをつけた場合は、その旧氏を記入してください。
D32: 旧氏の記載・変更 □ | X32: 旧氏の削除 □
D35: 通称に関する事項について届け出る場合は、以下のいずれかの□欄にチェックをつけてください。通称の記載にチェックをつけた場合は、その通称を記入してください。
D37: 通称の記載 □ | X37: 通称の削除 □
D40: 券面記載事項の変更に伴い失効する署名用電子証明書を発行する場合、□欄にチェックをつけてください。
D41: 申請内容 | J41: 署名用電子証明書の発行 □
D44: 代替対象 文字 の有無を以下に記入してください。
D45: 代替対象文字 の有無 | J45: （ 無 ・ 有 ） | O45: 常用している文字 | V45: （例． →吉）
D48: ※ | E48: 申請される方の住所、氏名のコンピュータ入力に際して、画面上に正確に表示されない文字（代替対象文字）があることを経験上ご存知の場合は、有に○を付けてください。 また、そのような場合に常用されている文字があれば、代わりに置き換える文字を選択する際の参考とするため、記入してください。分からない場合は、記入していただく必要はございません。
D49: 代理人による届出の場合は、以下に記入してください。
D50: 代理人 | X50: 本人との関係
D52: 住所
D54: 電話番号
D58: ※ 事務処理記載欄
D59: 受付担当者 | T59: 受付年月日
T60: 令和 年 月 日
D62: 署名用 電子証明書 | F62: 通信の有無 | P62: 破棄／職権失効の有無と回数 | AA62: 発行手数料額
F63: 1．無 2．有 （ ）回 | P63: 1．無 2．有 （ ）回 | AA63: 円
F65: 無通信、破棄／職権失効及び発行手数料無料の理由
D68: （参考）個人番号の記載がある場合は、生年月日と性別に加えて、住所の記載も省略することが可能です。
